<?xml version="1.0"?>
<robot xmlns:xacro="http://www.ros.org/wiki/xacro" name="my_robot">

    <material name="blue">
        <color rgba="0 0 0.8 1" />
    </material>
    <material name="black">
        <color rgba="0 0 0 1" />
    </material>
    <material name="white">
        <color rgba="1 1 1 1" />
    </material>

    <link name="base_link">
        <visual>
            <geometry>
                <cylinder radius="0.25" length="0.08" />
            </geometry>
            <material name="blue" />
        </visual>
        <collision>
            <geometry>
                <cylinder radius="0.25" length="0.08" />
            </geometry>
        </collision>
        <inertial>
            <mass value="2.0" />
            <inertia ixx="0.03" ixy="0" ixz="0" iyy="0.03" iyz="0" izz="0.06" />
        </inertial>
    </link>

    <link name="left_wheel">
        <visual>
            <geometry>
                <cylinder radius="0.05" length="0.04" />
            </geometry>
            <material name="black" />
        </visual>
        <collision>
            <geometry>
                <cylinder radius="0.05" length="0.04" />
            </geometry>
        </collision>
        <inertial>
            <mass value="0.2" />
            <inertia ixx="0.001" ixy="0" ixz="0" iyy="0.001" iyz="0" izz="0.001" />
        </inertial>
    </link>

    <joint name="left_wheel_joint" type="continuous">
        <parent link="base_link" />
        <child link="left_wheel" />
        <origin xyz="-0.1 0.15 -0.02" rpy="-1.5708 0 0" />
        <axis xyz="0 0 1" />
    </joint>

    <link name="right_wheel">
        <visual>
            <geometry>
                <cylinder radius="0.05" length="0.04" />
            </geometry>
            <material name="black" />
        </visual>
        <collision>
            <geometry>
                <cylinder radius="0.05" length="0.04" />
            </geometry>
        </collision>
        <inertial>
            <mass value="0.2" />
            <inertia ixx="0.001" ixy="0" ixz="0" iyy="0.001" iyz="0" izz="0.001" />
        </inertial>
    </link>

    <joint name="right_wheel_joint" type="continuous">
        <parent link="base_link" />
        <child link="right_wheel" />
        <origin xyz="-0.1 -0.15 -0.02" rpy="-1.5708 0 0" />
        <axis xyz="0 0 1" />
    </joint>

    <link name="caster_wheel">
        <visual>
            <geometry>
                <sphere radius="0.05" />
            </geometry>
            <material name="white" />
        </visual>
        <collision>
            <geometry>
                <sphere radius="0.05" />
            </geometry>
        </collision>
        <inertial>
            <mass value="0.1" />
            <inertia ixx="0.0001" ixy="0" ixz="0" iyy="0.0001" iyz="0" izz="0.0001" />
        </inertial>
    </link>

    <joint name="caster_joint" type="fixed">
        <parent link="base_link" />
        <child link="caster_wheel" />
        <origin xyz="0.18 0 -0.02" rpy="0 0 0" />
    </joint>

    <gazebo reference="caster_wheel">
        <mu1>0.001</mu1>
        <mu2>0.001</mu2>
        <material>Gazebo/White</material>
    </gazebo>
    <gazebo reference="base_link">
        <material>Gazebo/Blue</material>
    </gazebo>


    <link name="camera_link">
        <visual>
            <origin xyz="0 0 0" rpy="0 0 0" />
            <geometry>
                <box size="0.025 0.09 0.025" />
            </geometry>
            <material name="black" />
        </visual>
        <collision>
            <origin xyz="0 0 0" rpy="0 0 0" />
            <geometry>
                <box size="0.025 0.09 0.025" />
            </geometry>
        </collision>
        <inertial>
            <mass value="0.072" />
            <inertia ixx="0.001" ixy="0" ixz="0" iyy="0.001" iyz="0" izz="0.001" />
        </inertial>
    </link>

    <joint name="camera_joint" type="fixed">
        <parent link="base_link" />
        <child link="camera_link" />
        <origin xyz="0.30 0 1.00" rpy="0 1.5708 0" />
    </joint>

    <gazebo reference="camera_link">
        <sensor name="d435_camera" type="rgbd_camera">
            <topic>d435</topic>
            <update_rate>30</update_rate>
            <always_on>1</always_on>
            <visualize>true</visualize>
            <camera>
                <horizontal_fov>1.047</horizontal_fov>
                <image>
                    <width>640</width>
                    <height>480</height>
                    <format>R8G8B8</format>
                </image>
                <clip>
                    <near>0.1</near>
                    <far>10.0</far>
                </clip>
            </camera>
        </sensor>
    </gazebo>

    <gazebo>
        <plugin
            filename="gz-sim-diff-drive-system"
            name="gz::sim::systems::DiffDrive">
            <left_joint>left_wheel_joint</left_joint>
            <right_joint>right_wheel_joint</right_joint>
            <wheel_separation>0.40</wheel_separation>
            <wheel_radius>0.05</wheel_radius>
            <odom_publish_frequency>50</odom_publish_frequency>
            <topic>cmd_vel</topic>
            <odom_topic>odom</odom_topic>
            <frame_id>odom</frame_id>
            <child_frame_id>base_link</child_frame_id>
        </plugin>

        <plugin
            filename="gz-sim-joint-state-publisher-system"
            name="gz::sim::systems::JointStatePublisher">
        </plugin>

    </gazebo>

</robot>